Workbook

Sheet ОТЧЕТ 2026
B2: ОПЕРАТИВНАЯ ИНФОРМАЦИЯ ПО СБОРУ ГОРОШКА (СЕЗОН 2026 г.)
B19: ИЮНЬ
B20: Пн | C20: Вт | D20: Ср | E20: Чт | F20: Пт | G20: Сб | H20: Вс
B21: 1 | C21: =B21+1 -> 2 | D21: =C21+1 -> 3 | E21: =D21+1 -> 4 | F21: =E21+1 -> 5 | G21: =F21+1 -> 6 | H21: =G21+1 -> 7
B22: =H21+1 -> 8 | C22: =B22+1 -> 9 | D22: =C22+1 -> 10 | E22: =D22+1 -> 11 | F22: =E22+1 -> 12 | G22: =F22+1 -> 13 | H22: =G22+1 -> 14
B23: =H22+1 -> 15 | C23: =B23+1 -> 16 | D23: =C23+1 -> 17 | E23: =D23+1 -> 18 | F23: =E23+1 -> 19 | G23: =F23+1 -> 20 | H23: =G23+1 -> 21
B24: =H23+1 -> 22 | C24: =B24+1 -> 23 | D24: =C24+1 -> 24 | E24: =D24+1 -> 25 | F24: =E24+1 -> 26 | G24: =F24+1 -> 27 | H24: =G24+1 -> 28
B25: =H24+1 -> 29 | C25: =B25+1 -> 30
B26: ИЮЛЬ
D27: =1 -> 1 | E27: =D27+1 -> 2 | F27: =E27+1 -> 3 | G27: =F27+1 -> 4 | H27: =G27+1 -> 5
B28: =H27+1 -> 6 | C28: =B28+1 -> 7 | D28: =C28+1 -> 8 | E28: =D28+1 -> 9 | F28: =E28+1 -> 10 | G28: =F28+1 -> 11 | H28: =G28+1 -> 12
B29: =H28+1 -> 13 | C29: =B29+1 -> 14 | D29: =C29+1 -> 15 | E29: =D29+1 -> 16 | F29: =E29+1 -> 17 | G29: =F29+1 -> 18 | H29: =G29+1 -> 19
B31: День уборки - | E31: 7

Sheet Подробности1
A1: Сведения о Площадь уборки, га - Регистратор.Номенклатура: Авола, Поле: А-3, Дата отчета: 6/9/2026, Культура: ГРК (богара)
A3: Показатель | B3: Количество | C3: Значение финометра | D3: Регистратор.Номер | E3: Регистратор.Дата | F3: Регистратор.Вес брутто | G3: Регистратор.Вес нетто | H3: Регистратор.Вес тары | I3: Регистратор.Вес чистый | J3: Регистратор.Контрагент | K3: Регистратор.Номенклатура | L3: Регистратор.Комбайнеры.Поле.Наименование | M3: Регистратор.Водитель | N3: Регистратор.Время прибытия | O3: Регистратор.Время убытия | P3: Регистратор.Комбайнеры.Комбайнер.Наименование | Q3: Регистратор.Номера талонов | R3: Регистратор.Номер машины | S3: Регистратор.Номер прицепа | T3: Поле | U3: Сорт уточн | V3: Площадь уборки, га | W3: Культура | X3: Орошение | Y3: Смена | Z3: Дата отчета | AA3: Продажа | AB3: Примечание | AC3: Финометр | AD3: Характеристика | AE3: № акта | AF3: Дата акта | AG3: Вх № | AH3: Степень зрелости вспом
C4: 50 | D4: 157 | G4: 7110 | I4: 5510.3 | J4: ГРИН РЭЙ КУБАНЬ ООО | K4: Авола | M4: Ревенко Андрей Вячеславович | R4: А781РР | T4: А-3 | U4: Авола | W4: ГРК (богара) | X4: богара | Y4: 6 | Z4: 46182 | AC4: 40-52 | AD4: Высший | AE4: 103 | AF4: 46182 | AH4: 50
C5: 50 | D5: 156 | G5: 13160 | I5: 9935.8 | J5: ГРИН РЭЙ КУБАНЬ ООО | K5: Авола | M5: Сероштан Станислав Викторович | R5: Е758РЕ | T5: А-3 | U5: Авола | W5: ГРК (богара) | X5: богара | Y5: 6 | Z5: 46182 | AC5: 40-52 | AD5: Высший | AE5: 102 | AF5: 46182 | AH5: 50
C6: 48 | D6: 155 | G6: 13230 | I6: 9988.7 | J6: ГРИН РЭЙ КУБАНЬ ООО | K6: Авола | M6: Емец Р.А. | R6: У315НХ | T6: А-3 | U6: Авола | W6: ГРК (богара) | X6: богара | Y6: 6 | Z6: 46182 | AC6: 40-52 | AD6: Высший | AE6: 101 | AF6: 46182 | AH6: 48

Sheet Свод 2026
A1: Уборка гороха овощного в 2026 году на | C1: 46182
E3: Данные
A4: Культура | B4: Дата отчета | C4: Поле | D4: Регистратор.Номенклатура | E4: Площадь уборки, га | F4: Физический вес, кг | G4: Зачетный вес, кг | H4: в т.ч. Продажа, кг
A5: ГРК (богара) | B5: 46176 | C5: А-4/1 | D5: Тиара | E5: 36 | F5: 191510 | G5: 151574.5
B6: 46177 | C6: А-4/1 | D6: Тиара | E6: 20 | F6: 111250 | G6: 90266.7
C7: А-3 | D7: Авола | E7: 2 | F7: 6120 | G7: 4039.2
B8: 46179 | C8: А-4/1 | D8: Тиара | E8: 42 | F8: 244270 | G8: 195974.1
C9: А-22/1 | D9: Тиара | E9: 5 | F9: 24650 | G9: 20918.3
B10: 46180 | C10: А-4/1 | D10: Тиара | E10: 13 | F10: 61380 | G10: 49780.1
C11: А-3 | D11: Авола | E11: 30 | F11: 160930 | G11: 130624.7
B12: 46181 | C12: А-3 | D12: Авола | E12: 41 | F12: 246500 | G12: 202267.4
B13: 46182 | C13: А-3 | D13: Авола | E13: 6 | F13: 33500 | G13: 25434.8
C14: А-22/1 | D14: Увертюра | E14: 31 | F14: 206840 | G14: 180195.1 | H14: 32930
C15: А-23 | D15: Увертюра | E15: 9 | F15: 69350 | G15: 64079.6 | H15: 26130
A16: Итог Результат | E16: 235 | F16: 1356300 | G16: 1115154.5 | H16: 59060

Sheet Структура 2026 
A2: Структура посевных площадей
A4: Отбор: | B4: Год урожая Равно "2026 г." И Участок не используется Равно "Нет"
A6: Год урожая | D6: Площадь общая | E6: Площадь сева
A7: Подразделение
A8: Культура
A9: Поле
A10: 2026 г. | D10: 8282.66 | E10: 8282.66
A11: 2. Растениеводство (20) | D11: 5345 | E11: 5345
A12: Кукуруза на зерно | D12: 237 | E12: 237
A13: А-102/1 | D13: 5 | E13: 5
A14: А-103/1 | D14: 35 | E14: 35
A15: А-108/3 | D15: 9 | E15: 9
A16: А-109/1 | D16: 18 | E16: 18
A17: А-11 | D17: 17 | E17: 17
A18: А-110/1 | D18: 7 | E18: 7
A19: А-68/1 | D19: 77 | E19: 77
A20: А-84/1 | D20: 69 | E20: 69
A21: Подсолнечник | D21: 910 | E21: 910
... A165: Итого | D165: 8282.66 | E165: 8282.66

Sheet Сев 2026
D3: Значения
A4: Поле | B4: Номенклатура | C4: Сорт | D4: Площадь сева, га | E4: Всего внесено, ед. изм. | F4: Площадь обработанная, га
A5: А-104/1 | B5: Семена гороха ( п.е.) | C5: Женева 100 т.с. | D5: 11 | E5: 16 | F5: 1.5
B6: Семена гороха овощного протравленные | C6: Тристар 100 тыс.с (лот D0021 15 T25-3033ST) | D6: 11 | E6: 20 | F6: 1.5
B7: Семена гороха овощного протравленные (кг) | C7: Патриот ЭС | D7: 11 | E7: 2000 | F7: 8
A8: А-104/1 Итог | D8: 11 | E8: 2036 | F8: 11 | H8: =D8-F8 -> 0
A9: А-105/1 | B9: Семена гороха ( п.е.) | C9: Женева 100 т.с. | D9: 56 | E9: 20 | F9: 1.5
B10: Семена гороха овощного протравленные | C10: Авола 100 тыс.с (лот D0021 15 K25-6011ST) | D10: 56 | E10: 285 | F10: 24
C11: Авола 100 тыс.с (лот D0021 15 K25-6012ST) | D11: 56 | E11: 353 | F11: 30.5
A12: А-105/1 Итог | D12: 56 | E12: 658 | F12: 56 | H12: =D12-F12 -> 0
A13: А-111/1 | B13: Семена гороха овощного протравленные | C13: Авола 100 тыс.с (лот Kl1038104) | D13: 14 | E13: 177 | F13: 14
A14: А-111/1 Итог | D14: 14 | E14: 177 | F14: 14 | H14: =D14-F14 -> 0
A15: А-112/1 | B15: Семена гороха овощного протравленные | C15: Авола 100 тыс.с (лот Kl1038104) | D15: 40 | E15: 126 | F15: 10
C16: Тристар 100 тыс.с (лот ES1038103) | D16: 40 | E16: 390 | F16: 30
A17: А-112/1 Итог | D17: 40 | E17: 516 | F17: 40 | H17: =D17-F17 -> 0
A18: А-114 | B18: Семена гороха ( п.е.) | C18: Женева 100 т.с. | D18: 4 | E18: 52 | F18: 4
A19: А-114 Итог | D19: 4 | E19: 52 | F19: 4 | H19: =D19-F19 -> 0
A20: А-115/1 | B20: Семена гороха овощного протравленные | C20: Тристар 100 тыс.с (лот D0021 15 T25-3033ST) | D20: 63 | E20: 220 | F20: 21
C21: Тристар 100 тыс.с (лот ES1038103) | D21: 63 | E21: 515 | F21: 42
A22: А-115/1 Итог | D22: 63 | E22: 735 | F22: 63 | H22: =D22-F22 -> 0
A23: А-116/1 | B23: Семена гороха овощного протравленные | C23: Фаворит 100 т.с.(партия Н-Х/4402) | D23: 47 | E23: 160 | F23: 47 | J23: семенной участок
C24: Фаворит 100 т.с.(партия Н-Х/5126) | D24: 47 | E24: 377 | F24: 36
C25: Фаворит 100 т.с.(партия Н-Х/5128) | D25: 47 | E25: 120 | F25: 11
A26: А-116/1 Итог | D26: 47 | E26: 657 | F26: 94 | H26: =D26-F26 -> -47
A27: А-22/1 | B27: Семена гороха ( п.е.) | C27: Увертюра 100 000 | D27: 36 | E27: 426 | F27: 31
B28: Семена гороха овощного протравленные | C28: Тиара 100 т.с.(партия Н-Х/5120) | D28: 36 | E28: 90 | F28: 5
A29: А-22/1 Итог | D29: 36 | E29: 516 | F29: 36 | H29: =D29-F29 -> 0
A30: А-23 | B30: Семена гороха ( п.е.) | C30: Увертюра 100 000 | D30: 41 | E30: 274 | F30: 20
B31: Семена гороха овощного протравленные | C31: Фаворит 100 т.с.(партия Н-Х/5121) | D31: 41 | E31: 289 | F31: 21
A32: А-23 Итог | D32: 41 | E32: 563 | F32: 41 | H32: =D32-F32 -> 0
A33: А-24/1 | B33: Семена гороха овощного протравленные | C33: Фаворит 100 т.с.(партия Н-Х/5121) | D33: 39 | E33: 523 | F33: 39
A34: А-24/1 Итог | D34: 39 | E34: 523 | F34: 39 | H34: =D34-F34 -> 0
A35: А-3 | B35: Семена гороха овощного протравленные | C35: Авола 100 тыс.с (лот D0021 15 K25-6011ST) | D35: 79 | E35: 270 | F35: 34
C36: Авола 100 тыс.с (лот Kl1038104) | D36: 79 | E36: 359 | F36: 45
B37: Семена гороха овощного протравленные (кг) | C37: Преладо | D37: 79 | E37: 8410 | F37: 79 | J37: подсев
A38: А-3 Итог | D38: 79 | E38: 9039 | F38: 158 | H38: =D38-F38 -> -79
A39: А-38 | B39: Семена гороха овощного протравленные | C39: Авола 100 тыс.с (лот Kl1038104) | D39: 38 | E39: 302 | F39: 38
B40: Семена гороха овощного протравленные (кг) | C40: Преладо | D40: 38 | E40: 4040 | F40: 38 | J40: подсев
A41: А-38 Итог | D41: 38 | E41: 4342 | F41: 76 | H41: =D41-F41 -> -38
A42: А-4/1 | B42: Семена гороха овощного протравленные | C42: Тиара 100 т.с.(партия Н-Х/5116) | D42: 111 | E42: 700 | F42: 62
...

Sheet Данные 2026
K1: протянуть формулу на след день
A2: 1.1 | B2: Выборка по КА, орошению | D2: 5 | I2: 8
A3: Валовый сбор | D3: Выполнение плана по сбору | E3: ПЛАН, т | F3: ФАКТ, т | G3: Исполнение плана, % | I3: Ежедневные показатели | K3: Сбор, т | L3: Значение спелости | M3: Финометр
A4: ПЛАН, т | B4: =C59 -> 9535.8 | D4: ГРК (богара) | E4: =C55 -> 3890 | F4: =D55 -> 1356.3 | G4: =IFERROR(F4/E4, ) -> 0.34866324 | I4: 1 | J4: 46176 | K4: =IFERROR(SUMIF('Реестр уборки 2026'!Z:Z,J4,'Реестр уборки 2026'!G:G)/1000, ) -> 191.51 | L4: =IFERROR(AVERAGEIF('Реестр уборки 2026'!Z:Z,'Данные 2026'!J4,'Реестр уборки 2026'!C:C),) -> 52.285714 | M4: нет данных
A5: ФАКТ, т | B5: =D59 -> 1356.3 | D5: ГРК (полив) | E5: =C56 -> 2100 | F5: =D56 -> 0 | G5: =IFERROR(F5/E5, ) -> 0 | I5: 2 | J5: =J4+1 -> 46177 | K5: =IFERROR(SUMIF('Реестр уборки 2026'!Z:Z,J5,'Реестр уборки 2026'!G:G)/1000, ) -> 117.37 | L5: =IFERROR(AVERAGEIF('Реестр уборки 2026'!Z:Z,'Данные 2026'!J5,'Реестр уборки 2026'!C:C),) -> 52 | M5: нет данных
A6: Исполнение плана, % | B6: =E59 -> 0.14223243 | D6: Агролидер (полив) | E6: =C57 -> 1345 | F6: =D57 -> 0 | G6: =IFERROR(F6/E6, ) -> 0 | I6: 3 | J6: =J5+1 -> 46178 | M6: нет данных
D7: Колос (полив) | E7: =C58 -> 2200.8 | F7: =D58 -> 0 | G7: =IFERROR(F7/E7, ) -> 0 | I7: 4 | J7: =J6+1 -> 46179 | K7: =IFERROR(SUMIF('Реестр уборки 2026'!Z:Z,J7,'Реестр уборки 2026'!G:G)/1000, ) -> 268.92 | L7: =IFERROR(AVERAGEIF('Реестр уборки 2026'!Z:Z,'Данные 2026'!J7,'Реестр уборки 2026'!C:C),) -> 47.826087 | M7: нет данных
A8: 1.2 | I8: 5 | J8: =J7+1 -> 46180 | K8: =IFERROR(SUMIF('Реестр уборки 2026'!Z:Z,J8,'Реестр уборки 2026'!G:G)/1000, ) -> 222.31 | L8: =IFERROR(AVERAGEIF('Реестр уборки 2026'!Z:Z,'Данные 2026'!J8,'Реестр уборки 2026'!C:C),) -> 51.2 | M8: нет данных
A9: Зачетный вес | I9: 6 | J9: =J8+1 -> 46181 | K9: =IFERROR(SUMIF('Реестр уборки 2026'!Z:Z,J9,'Реестр уборки 2026'!G:G)/1000, ) -> 246.5 | L9: =IFERROR(AVERAGEIF('Реестр уборки 2026'!Z:Z,'Данные 2026'!J9,'Реестр уборки 2026'!C:C),) -> 49.55 | M9: нет данных
A10: ПЛАН, т | I10: 7 | J10: =J9+1 -> 46182 | K10: =IFERROR(SUMIF('Реестр уборки 2026'!Z:Z,J10,'Реестр уборки 2026'!G:G)/1000, ) -> 309.69 | L10: =AVERAGEIF('Реестр уборки 2026'!Z88:Z109,'Данные 2026'!J10,'Реестр уборки 2026'!C88:C109) -> 53.272727 | M10: нет данных
A11: ФАКТ, т | I11: 8 | J11: =J10+1 -> 46183 | M11: нет данных
E12: =SUM(E4:E11) -> 9535.8 | F12: =SUM(F4:F11) -> 1356.3 | G12: =IFERROR(F12/E12, ) -> 0.14223243 | I12: 9 | J12: =J11+1 -> 46184 | M12: нет данных
A13: 2 | D13: 6 | I13: 10 | J13: =J12+1 -> 46185 | M13: нет данных
A14: Площадь уборки | D14: Выполнение плана по сбору | F14: Урожайность, т/га | G14: Вал, т | I14: 11 | J14: =J13+1 -> 46186 | M14: нет данных
A15: ПЛАН, га | B15: =F59 -> 1907.16 | D15: 2019 | F15: 3.3 | G15: 6813 | I15: 12 | J15: =J14+1 -> 46187 | M15: нет данных
A16: ФАКТ, га | B16: =G59 -> 235 | D16: 2020 | F16: 4.6 | G16: 12761 | I16: 13 | J16: =J15+1 -> 46188 | M16: нет данных
A17: Остаток, га | B17: =B15-B16 -> 1672.16 | D17: 2021 | F17: 4.2 | G17: 10161 | I17: 14 | J17: =J16+1 -> 46189 | M17: нет данных
A18: Исполнение плана, % | B18: =B16/B15 -> 0.12321987 | D18: 2022 | F18: 3 | G18: 6505 | I18: 15 | J18: =J17+1 -> 46190 | M18: нет данных
A19: Убрали на зерно | D19: 2023 | F19: 5.6 | G19: 6656 | I19: 16 | J19: =J18+1 -> 46191 | M19: нет данных
A20: ОСТАВИЛИ | D20: 2024 | F20: 2.7 | G20: 4371.9 | I20: 17 | J20: =J19+1 -> 46192 | M20: нет данных
A21: 3.1 | D21: 2025 | F21: 4.7835642 | G21: 7098.14 | I21: 18 | J21: =J20+1 -> 46193 | M21: нет данных
A22: Урожайность физ. вес. | D22: 2026 | F22: =B24 -> 5.7714894 | G22: =F12 -> 1356.3 | I22: 19 | J22: =J21+1 -> 46194 | M22: нет данных
A23: ПЛАН, т/га | B23: =IFERROR(B4/B15, ) -> 5 | I23: 20 | J23: =J22+1 -> 46195 | M23: нет данных
A24: ФАКТ, т/га | B24: =IFERROR(B5/B16, ) -> 5.7714894 | I24: 21 | J24: =J23+1 -> 46196 | M24: нет данных
D25: 7 | I25: 22 | J25: =J24+1 -> 46197 | M25: нет данных
A26: 3.2 | D26: Распределение сырья по финометру | F26: Вес, т | G26: Доля, % | I26: 23 | J26: =J25+1 -> 46198 | M26: нет данных
A27: Урожайность зач. вес. | C27: до 40 | D27: до 40 | F27: =SUMIF('Реестр уборки 2026'!AC:AC,Таблица111[[#This Row],[Распределение сырья по финометру]],'Реестр уборки 2026'!G:G)/1000 -> 0 | G27: =IFERROR(F27/$F$33, ) -> 0 | I27: 24 | J27: =J26+1 -> 46199 | M27: нет данных
A28: ПЛАН, т/га | B28: =IFERROR(B10/B15, 0) -> 0 | C28: 40-62 | D28: 40-52 | F28: =SUMIF('Реестр уборки 2026'!AC:AC,Таблица111[[#This Row],[Распределение сырья по финометру]],'Реестр уборки 2026'!G:G)/1000 -> 787.55 | G28: =IFERROR(F28/$F$33, ) -> 0.58066062 | I28: 25 | J28: =J27+1 -> 46200 | M28: нет данных
A29: ФАКТ, т/га | B29: =IFERROR(B11/B16, 0) -> 0 | C29: 63-66 | D29: 53-63 | F29: =SUMIF('Реестр уборки 2026'!AC:AC,Таблица111[[#This Row],[Распределение сырья по финометру]],'Реестр уборки 2026'!G:G)/1000 -> 509.69 | G29: =IFERROR(F29/$F$33, ) -> 0.37579444 | I29: 26 | J29: =J28+1 -> 46201 | M29: нет данных
C30: 67-85 | D30: 64-66 | F30: =SUMIF('Реестр уборки 2026'!AC:AC,Таблица111[[#This Row],[Распределение сырья по финометру]],'Реестр уборки 2026'!G:G)/1000 -> 0 | G30: =IFERROR(F30/$F$33, ) -> 0 | I30: 27 | J30: =J29+1 -> 46202 | M30: нет данных
D31: 67-85 | F31: =SUMIF('Реестр уборки 2026'!AC:AC,Таблица111[[#This Row],[Распределение сырья по финометру]],'Реестр уборки 2026'!G:G)/1000 -> 0 | G31: =IFERROR(F31/$F$33, ) -> 0 | I31: 28 | J31: =J30+1 -> 46203 | M31: нет данных
A32: 4 | D32: нет данных | F32: =SUMIF('Реестр уборки 2026'!AC:AC,Таблица111[[#This Row],[Распределение сырья по финометру]],'Реестр уборки 2026'!G:G)/1000 -> 59.06 | G32: =IFERROR(F32/$F$33, ) -> 0.043544938 | I32: 29 | J32: =J31+1 -> 46204 | M32: нет данных
A33: Информация по сырью | F33: =SUM(F27:F32) -> 1356.3 | G33: =SUM(G27:G32) -> 1 | I33: 30 | J33: =J32+1 -> 46205 | M33: нет данных
A34: Переработка | B34: =B37-B35-B36 -> 1297.24 | I34: 31 | J34: =J33+1 -> 46206 | M34: нет данных
A35: Утилизация | B35: 0 | I35: 32 | J35: =J34+1 -> 46207 | M35: нет данных
A36: Реализация | B36: =59060/1000 -> 59.06 | C36: 0 | D36: - реализовано по документам отгрузки (зач вес) | I36: 33 | J36: =J35+1 -> 46208 | M36: нет данных
A37: Собственное сырье | B37: =F12 -> 1356.3 | I37: 34 | J37: =J36+1 -> 46209 | M37: нет данных
A38: Закупка | B38: 0 | I38: 35 | J38: =J37+1 -> 46210 | M38: нет данных
I39: 36 | J39: =J38+1 -> 46211 | M39: нет данных
I40: 37 | J40: =J39+1 -> 46212 | M40: нет данных
...

Sheet ОТЧЕТ 2025
B2: ОПЕРАТИВНАЯ ИНФОРМАЦИЯ ПО СБОРУ ГОРОШКА (СЕЗОН 2025 г.)
B24: МАЙ
B25: Пн | C25: Вт | D25: Ср | E25: Чт | F25: Пт | G25: Сб | H25: Вс
C26: 45804 | D26: =C26+1 -> 45805 | E26: =D26+1 -> 45806 | F26: =E26+1 -> 45807 | G26: =F26+1 -> 45808
B27: ИЮНЬ
H28: =G26+1 -> 45809
B29: =H28+1 -> 45810 | C29: =B29+1 -> 45811 | D29: =C29+1 -> 45812 | E29: =D29+1 -> 45813 | F29: =E29+1 -> 45814 | G29: =F29+1 -> 45815 | H29: =G29+1 -> 45816
B30: =H29+1 -> 45817 | C30: =B30+1 -> 45818 | D30: =C30+1 -> 45819 | E30: =D30+1 -> 45820 | F30: =E30+1 -> 45821 | G30: =F30+1 -> 45822 | H30: =G30+1 -> 45823
B31: =H30+1 -> 45824 | C31: =B31+1 -> 45825 | D31: =C31+1 -> 45826 | E31: =D31+1 -> 45827 | F31: =E31+1 -> 45828 | G31: =F31+1 -> 45829 | H31: =G31+1 -> 45830
B32: =H31+1 -> 45831 | C32: =B32+1 -> 45832 | D32: =C32+1 -> 45833 | E32: =D32+1 -> 45834 | F32: =E32+1 -> 45835 | G32: =F32+1 -> 45836 | H32: =G32+1 -> 45837
B33: =H32+1 -> 45838
B34: ИЮЛЬ
C35: =B33+1 -> 45839 | D35: =C35+1 -> 45840 | E35: =D35+1 -> 45841 | F35: =E35+1 -> 45842 | G35: =F35+1 -> 45843 | H35: =G35+1 -> 45844
B36: =H35+1 -> 45845 | C36: =B36+1 -> 45846 | D36: =C36+1 -> 45847 | E36: =D36+1 -> 45848 | F36: =E36+1 -> 45849 | G36: =F36+1 -> 45850 | H36: =G36+1 -> 45851
B38: День уборки - | E38: 45

Sheet ОТЧЕТ 2024
B2: ОПЕРАТИВНАЯ ИНФОРМАЦИЯ ПО СБОРУ ГОРОШКА (СЕЗОН 2024 г.)
B21: МАЙ
B22: Пн | C22: Вт | D22: Ср | E22: Чт | F22: Пт | G22: Сб | H22: Вс
F23: 45429 | G23: 45430 | H23: 45431
B24: =H23+1 -> 45432 | C24: =B24+1 -> 45433 | D24: =C24+1 -> 45434 | E24: =D24+1 -> 45435 | F24: =E24+1 -> 45436 | G24: =F24+1 -> 45437 | H24: =G24+1 -> 45438
B25: =H24+1 -> 45439 | C25: =B25+1 -> 45440 | D25: =C25+1 -> 45441 | E25: =D25+1 -> 45442 | F25: =E25+1 -> 45443
B26: ИЮНЬ
G27: 45444 | H27: =G27+1 -> 45445
B28: =H27+1 -> 45446 | C28: =B28+1 -> 45447 | D28: =C28+1 -> 45448 | E28: =D28+1 -> 45449 | F28: =E28+1 -> 45450 | G28: =F28+1 -> 45451 | H28: =G28+1 -> 45452
B29: =H28+1 -> 45453 | C29: =B29+1 -> 45454 | D29: =C29+1 -> 45455 | E29: =D29+1 -> 45456 | F29: =E29+1 -> 45457 | G29: =F29+1 -> 45458 | H29: =G29+1 -> 45459
B30: =H29+1 -> 45460 | C30: =B30+1 -> 45461 | D30: =C30+1 -> 45462 | E30: =D30+1 -> 45463 | F30: =E30+1 -> 45464 | G30: =F30+1 -> 45465 | H30: =G30+1 -> 45466
B31: =H30+1 -> 45467 | C31: =B31+1 -> 45468 | D31: =C31+1 -> 45469 | E31: =D31+1 -> 45470 | F31: =E31+1 -> 45471 | G31: =F31+1 -> 45472 | H31: =G31+1 -> 45473
B32: ИЮЛЬ
B33: =H31+1 -> 45474 | C33: =B33+1 -> 45475 | D33: =C33+1 -> 45476 | E33: =D33+1 -> 45477 | F33: =E33+1 -> 45478 | G33: =F33+1 -> 45479 | H33: =G33+1 -> 45480
B34: =H33+1 -> 45481 | C34: =B34+1 -> 45482 | D34: =C34+1 -> 45483 | E34: =D34+1 -> 45484 | F34: =E34+1 -> 45485 | G34: =F34+1 -> 45486 | H34: =G34+1 -> 45487
B35: =H34+1 -> 45488 | C35: =B35+1 -> 45489 | D35: =C35+1 -> 45490 | E35: =D35+1 -> 45491 | F35: =E35+1 -> 45492 | G35: =F35+1 -> 45493 | H35: =G35+1 -> 45494
B36: =H35+1 -> 45495 | C36: =B36+1 -> 45496 | D36: =C36+1 -> 45497 | E36: =D36+1 -> 45498 | F36: =E36+1 -> 45499 | G36: =F36+1 -> 45500 | H36: =G36+1 -> 45501
B37: =H36+1 -> 45502 | C37: =B37+1 -> 45503 | D37: =C37+1 -> 45504

Sheet Данные 2025
A2: 1.1 | B2: Выборка по КА, орошению | D2: 5 | I2: 8
A3: Валовый сбор | D3: Выполнение плана по сбору | E3: ПЛАН, т | F3: ФАКТ, т | G3: Исполнение плана, % | I3: Ежедневные показатели | K3: Сбор, т | L3: Значение спелости | M3: Финометр
A4: ПЛАН, т | B4: =C63 -> 6798.045 | D4: Учхоз Кубань (богара) | E4: 1157.4 | F4: =D55 -> 1320.13 | G4: =IFERROR(F4/E4, ) -> 1.1405996 | I4: 1 | J4: 45804 | K4: =SUMIF('Реестр уборки 2025'!Z:Z,J4,'Реестр уборки 2025'!G:G)/1000 -> 71.35 | L4: =IFERROR(AVERAGEIF('Реестр уборки 2025'!Z:Z,'Данные 2025'!J4,'Реестр уборки 2025'!C:C),) -> 41.333333 | M4: 40-52
A5: ФАКТ, т | B5: =D63 -> 7098.14 | D5: ГРК собственные семена (богара) | E5: 910 | F5: =D56 -> 503.65 | G5: =IFERROR(F5/E5, ) -> 0.55346154 | I5: 2 | J5: 45805 | K5: =SUMIF('Реестр уборки 2025'!Z:Z,J5,'Реестр уборки 2025'!G:G)/1000 -> 98.78 | L5: =IFERROR(AVERAGEIF('Реестр уборки 2025'!Z:Z,'Данные 2025'!J5,'Реестр уборки 2025'!C:C),) -> 44 | M5: 40-52
A6: Исполнение плана, % | B6: =E63 -> 1.0441443 | D6: ГРК демо (богара) | E6: 136.5 | F6: =D57 -> 91.8 | G6: =IFERROR(F6/E6, ) -> 0.67252747 | I6: 3 | J6: 45806 | K6: =SUMIF('Реестр уборки 2025'!Z:Z,J6,'Реестр уборки 2025'!G:G)/1000 -> 10.74 | L6: =IFERROR(AVERAGEIF('Реестр уборки 2025'!Z:Z,'Данные 2025'!J6,'Реестр уборки 2025'!C:C),) -> 42.5 | M6: 40-52
D7: ГРК (богара) | E7: 936.2 | F7: =D58 -> 769.25 | G7: =IFERROR(F7/E7, ) -> 0.82167272 | I7: 4 | J7: 45807
A8: 1.2 | D8: Братковский (полив) | E8: 765 | F8: =D59 -> 842.08 | G8: =IFERROR(F8/E8, ) -> 1.1007582 | I8: 5 | J8: 45808 | K8: =SUMIF('Реестр уборки 2025'!Z:Z,J8,'Реестр уборки 2025'!G:G)/1000 -> 55.61 | L8: =IFERROR(AVERAGEIF('Реестр уборки 2025'!Z:Z,'Данные 2025'!J8,'Реестр уборки 2025'!C:C),) -> 45.625 | M8: 40-52
A9: Зачетный вес | D9: Братковский закупка (полив) | E9: 522.325 | F9: =D60 -> 561.3 | G9: =IFERROR(F9/E9, ) -> 1.0746183 | I9: 6 | J9: 45809 | K9: =SUMIF('Реестр уборки 2025'!Z:Z,J9,'Реестр уборки 2025'!G:G)/1000 -> 206.19 | L9: =IFERROR(AVERAGEIF('Реестр уборки 2025'!Z:Z,'Данные 2025'!J9,'Реестр уборки 2025'!C:C),) -> 51.588235 | M9: 40-52
A10: ПЛАН, т | D10: Агролидер (полив) | E10: 586.5 | F10: =D61 -> 1017.73 | G10: =IFERROR(F10/E10, ) -> 1.73526 | I10: 7 | J10: 45810 | K10: =SUMIF('Реестр уборки 2025'!Z:Z,J10,'Реестр уборки 2025'!G:G)/1000 -> 198.3 | L10: =IFERROR(AVERAGEIF('Реестр уборки 2025'!Z:Z,'Данные 2025'!J10,'Реестр уборки 2025'!C:C),) -> 52.9375 | M10: 53-63
A11: ФАКТ, т | D11: Колос (полив) | E11: 1784.12 | F11: =D62 -> 1992.2 | G11: =IFERROR(F11/E11, ) -> 1.1166289 | I11: 8 | J11: 45811 | K11: =SUMIF('Реестр уборки 2025'!Z:Z,J11,'Реестр уборки 2025'!G:G)/1000 -> 285.91 | L11: =IFERROR(AVERAGEIF('Реестр уборки 2025'!Z:Z,'Данные 2025'!J11,'Реестр уборки 2025'!C:C),) -> 54.666667 | M11: 53-63
E12: =SUM(E4:E11) -> 6798.045 | F12: =SUM(F4:F11) -> 7098.14 | G12: =IFERROR(F12/E12, ) -> 1.0441443 | I12: 9 | J12: 45812 | K12: =SUMIF('Реестр уборки 2025'!Z:Z,J12,'Реестр уборки 2025'!G:G)/1000 -> 339.79 | L12: =IFERROR(AVERAGEIF('Реестр уборки 2025'!Z:Z,'Данные 2025'!J12,'Реестр уборки 2025'!C:C),) -> 57.666667 | M12: 53-63
A13: 2 | D13: 6 | I13: 10 | J13: 45813 | K13: =SUMIF('Реестр уборки 2025'!Z:Z,J13,'Реестр уборки 2025'!G:G)/1000 -> 240.45 | L13: =IFERROR(AVERAGEIF('Реестр уборки 2025'!Z:Z,'Данные 2025'!J13,'Реестр уборки 2025'!C:C),) -> 53.473684 | M13: 53-63
A14: Площадь уборки | D14: Выполнение плана по сбору | F14: Урожайность, т/га | G14: Вал, т | I14: 11 | J14: 45814 | K14: =SUMIF('Реестр уборки 2025'!Z:Z,J14,'Реестр уборки 2025'!G:G)/1000 -> 417.43 | L14: =IFERROR(AVERAGEIF('Реестр уборки 2025'!Z:Z,'Данные 2025'!J14,'Реестр уборки 2025'!C:C),) -> 57.228571 | M14: 53-63
A15: ПЛАН, га | B15: =F63 -> 1675.8 | D15: 2019 | F15: 3.3 | G15: 6813 | I15: 12 | J15: 45815 | K15: =SUMIF('Реестр уборки 2025'!Z:Z,J15,'Реестр уборки 2025'!G:G)/1000 -> 163.35 | L15: =IFERROR(AVERAGEIF('Реестр уборки 2025'!Z:Z,'Данные 2025'!J15,'Реестр уборки 2025'!C:C),) -> 60.933333 | M15: 53-63
A16: ФАКТ, га | B16: =G63 -> 1483.8601 | D16: 2020 | F16: 4.6 | G16: 12761 | I16: 13 | J16: 45816 | K16: =SUMIF('Реестр уборки 2025'!Z:Z,J16,'Реестр уборки 2025'!G:G)/1000 -> 233.26 | L16: =IFERROR(AVERAGEIF('Реестр уборки 2025'!Z:Z,'Данные 2025'!J16,'Реестр уборки 2025'!C:C),) -> 60.869565 | M16: 53-63
A17: Остаток, га | B17: =B15-B16 -> 191.93991 | D17: 2021 | F17: 4.2 | G17: 10161 | I17: 14 | J17: 45817 | K17: =SUMIF('Реестр уборки 2025'!Z:Z,J17,'Реестр уборки 2025'!G:G)/1000 -> 100.73 | L17: =IFERROR(AVERAGEIF('Реестр уборки 2025'!Z:Z,'Данные 2025'!J17,'Реестр уборки 2025'!C:C),) -> 68.1 | M17: 67-85
A18: Исполнение плана, % | B18: =B16/B15 -> 0.88546371 | D18: 2022 | F18: 3 | G18: 6505 | I18: 15 | J18: 45818 | K18: =SUMIF('Реестр уборки 2025'!Z:Z,J18,'Реестр уборки 2025'!G:G)/1000 -> 243.58 | L18: =IFERROR(AVERAGEIF('Реестр уборки 2025'!Z:Z,'Данные 2025'!J18,'Реестр уборки 2025'!C:C),) -> 62.541667 | M18: 53-63
A19: Убрали на зерно | B19: 71 | D19: 2023 | F19: 5.6 | G19: 6656 | I19: 16 | J19: 45819 | K19: =SUMIF('Реестр уборки 2025'!Z:Z,J19,'Реестр уборки 2025'!G:G)/1000 -> 127.99 | L19: =IFERROR(AVERAGEIF('Реестр уборки 2025'!Z:Z,'Данные 2025'!J19,'Реестр уборки 2025'!C:C),) -> 65.090909 | M19: 64-66
A20: ОСТАВИЛИ | B20: 120.96957 | D20: 2024 | F20: 2.7 | G20: 4371.9 | I20: 17 | J20: 45820 | K20: =SUMIF('Реестр уборки 2025'!Z:Z,J20,'Реестр уборки 2025'!G:G)/1000 -> 302.41 | L20: =IFERROR(AVERAGEIF('Реестр уборки 2025'!Z:Z,'Данные 2025'!J20,'Реестр уборки 2025'!C:C),) -> 54.217391 | M20: 53-63
A21: 3.1 | D21: 2025 | F21: =B24 -> 4.7835642 | G21: =F12 -> 7098.14 | I21: 18 | J21: 45821 | K21: =SUMIF('Реестр уборки 2025'!Z:Z,J21,'Реестр уборки 2025'!G:G)/1000 -> 251.82 | L21: =IFERROR(AVERAGEIF('Реестр уборки 2025'!Z:Z,'Данные 2025'!J21,'Реестр уборки 2025'!C:C),) -> 53.583333 | M21: 53-63
A22: Урожайность физ. вес. | I22: 19 | J22: 45822 | K22: =SUMIF('Реестр уборки 2025'!Z:Z,J22,'Реестр уборки 2025'!G:G)/1000 -> 260.19 | L22: =IFERROR(AVERAGEIF('Реестр уборки 2025'!Z:Z,'Данные 2025'!J22,'Реестр уборки 2025'!C:C),) -> 63.15 | M22: 53-63
A23: ПЛАН, т/га | B23: =IFERROR(B4/B15, ) -> 4.0565968 | I23: 20 | J23: 45823 | K23: =SUMIF('Реестр уборки 2025'!Z:Z,J23,'Реестр уборки 2025'!G:G)/1000 -> 251.63 | L23: =IFERROR(AVERAGEIF('Реестр уборки 2025'!Z:Z,'Данные 2025'!J23,'Реестр уборки 2025'!C:C),) -> 67.095238 | M23: 67-85
A24: ФАКТ, т/га | B24: =IFERROR(B5/B16, ) -> 4.7835642 | I24: 21 | J24: 45824 | K24: =SUMIF('Реестр уборки 2025'!Z:Z,J24,'Реестр уборки 2025'!G:G)/1000 -> 182.08 | L24: =IFERROR(AVERAGEIF('Реестр уборки 2025'!Z:Z,'Данные 2025'!J24,'Реестр уборки 2025'!C:C),) -> 61.375 | M24: 53-63
D25: 7 | I25: 22 | J25: 45825 | K25: =SUMIF('Реестр уборки 2025'!Z:Z,J25,'Реестр уборки 2025'!G:G)/1000 -> 231.15 | L25: =IFERROR(AVERAGEIF('Реестр уборки 2025'!Z:Z,'Данные 2025'!J25,'Реестр уборки 2025'!C:C),) -> 58.117647 | M25: 53-63
A26: 3.2 | D26: Распределение сырья по финометру | F26: Вес, т | G26: Доля, % | I26: 23 | J26: 45826 | K26: =SUMIF('Реестр уборки 2025'!Z:Z,J26,'Реестр уборки 2025'!G:G)/1000 -> 157.45 | L26: =IFERROR(AVERAGEIF('Реестр уборки 2025'!Z:Z,'Данные 2025'!J26,'Реестр уборки 2025'!C:C),) -> 55.5 | M26: 53-63
A27: Урожайность зач. вес. | C27: до 40 | D27: до 40 | F27: =SUMIF('Реестр уборки 2025'!AC:AC,Таблица1[[#This Row],[Распределение сырья по финометру]],'Реестр уборки 2025'!G:G)/1000 -> 15.6 | G27: =IFERROR(F27/$F$33, ) -> 0.0021977588 | I27: 24 | J27: 45827 | K27: =SUMIF('Реестр уборки 2025'!Z:Z,J27,'Реестр уборки 2025'!G:G)/1000 -> 304.92 | L27: =IFERROR(AVERAGEIF('Реестр уборки 2025'!Z:Z,'Данные 2025'!J27,'Реестр уборки 2025'!C:C),) -> 62.826087 | M27: 53-63
A28: ПЛАН, т/га | B28: =IFERROR(B10/B15, 0) -> 0 | C28: 40-62 | D28: 40-52 | F28: =SUMIF('Реестр уборки 2025'!AC:AC,Таблица1[[#This Row],[Распределение сырья по финометру]],'Реестр уборки 2025'!G:G)/1000 -> 1875.175 | G28: =IFERROR(F28/$F$33, ) -> 0.26417836 | I28: 25 | J28: 45828 | K28: =SUMIF('Реестр уборки 2025'!Z:Z,J28,'Реестр уборки 2025'!G:G)/1000 -> 252.94 | L28: =IFERROR(AVERAGEIF('Реестр уборки 2025'!Z:Z,'Данные 2025'!J28,'Реестр уборки 2025'!C:C),) -> 64.526316 | M28: 64-66
A29: ФАКТ, т/га | B29: =IFERROR(B11/B16, 0) -> 0 | C29: 63-66 | D29: 53-63 | F29: =SUMIF('Реестр уборки 2025'!AC:AC,Таблица1[[#This Row],[Распределение сырья по финометру]],'Реестр уборки 2025'!G:G)/1000 -> 3153.785 | G29: =IFERROR(F29/$F$33, ) -> 0.44431147 | I29: 26 | J29: 45829 | K29: =SUMIF('Реестр уборки 2025'!Z:Z,J29,'Реестр уборки 2025'!G:G)/1000 -> 123.3 | L29: =IFERROR(AVERAGEIF('Реестр уборки 2025'!Z:Z,'Данные 2025'!J29,'Реестр уборки 2025'!C:C),) -> 60 | M29: 53-63
C30: 67-85 | D30: 64-66 | F30: =SUMIF('Реестр уборки 2025'!AC:AC,Таблица1[[#This Row],[Распределение сырья по финометру]],'Реестр уборки 2025'!G:G)/1000 -> 570.75 | G30: =IFERROR(F30/$F$33, ) -> 0.080408389 | I30: 27 | J30: 45830 | K30: =SUMIF('Реестр уборки 2025'!Z:Z,J30,'Реестр уборки 2025'!G:G)/1000 -> 272.42 | L30: =IFERROR(AVERAGEIF('Реестр уборки 2025'!Z:Z,'Данные 2025'!J30,'Реестр уборки 2025'!C:C),) -> 49.4 | M30: 40-52
D31: 67-85 | F31: =SUMIF('Реестр уборки 2025'!AC:AC,Таблица1[[#This Row],[Распределение сырья по финометру]],'Реестр уборки 2025'!G:G)/1000 -> 1443.44 | G31: =IFERROR(F31/$F$33, ) -> 0.20335468 | I31: 28 | J31: 45831 | K31: =SUMIF('Реестр уборки 2025'!Z:Z,J31,'Реестр уборки 2025'!G:G)/1000 -> 109.28 | L31: =IFERROR(AVERAGEIF('Реестр уборки 2025'!Z:Z,'Данные 2025'!J31,'Реестр уборки 2025'!C:C),) -> 52.875 | M31: 53-63
A32: 4 | D32: нет данных | F32: =SUMIF('Реестр уборки 2025'!AC:AC,Таблица1[[#This Row],[Распределение сырья по финометру]],'Реестр уборки 2025'!G:G)/1000 -> 39.39 | G32: =IFERROR(F32/$F$33, ) -> 0.0055493411 | I32: 29 | J32: 45832 | K32: =SUMIF('Реестр уборки 2025'!Z:Z,J32,'Реестр уборки 2025'!G:G)/1000 -> 200.28 | L32: =IFERROR(AVERAGEIF('Реестр уборки 2025'!Z:Z,'Данные 2025'!J32,'Реестр уборки 2025'!C:C),) -> 49.375 | M32: 40-52
A33: Информация по сырью | F33: =SUM(F27:F32) -> 7098.14 | G33: =SUM(G27:G32) -> 1 | I33: 30 | J33: 45833 | K33: =SUMIF('Реестр уборки 2025'!Z:Z,J33,'Реестр уборки 2025'!G:G)/1000 -> 19.23 | L33: =IFERROR(AVERAGEIF('Реестр уборки 2025'!Z:Z,'Данные 2025'!J33,'Реестр уборки 2025'!C:C),) -> 48.5 | M33: 40-52
A34: Переработка | B34: =B37-B35-B36 -> 6329.53 | I34: 31 | J34: 45834
A35: Утилизация | B35: =(108250+8280+39390)/1000 -> 155.92 | I35: 32 | J35: 45835 | K35: =SUMIF('Реестр уборки 2025'!Z:Z,J35,'Реестр уборки 2025'!G:G)/1000 -> 17.56 | L35: =IFERROR(AVERAGEIF('Реестр уборки 2025'!Z:Z,'Данные 2025'!J35,'Реестр уборки 2025'!C:C),) -> 46 | M35: 40-52
A36: Реализация | B36: 612.69 | C36: 542.3951 | D36: - реализовано по документам отгрузки (ранее было указано в отчете) | I36: 33 | J36: 45836 | K36: =SUMIF('Реестр уборки 2025'!Z:Z,J36,'Реестр уборки 2025'!G:G)/1000 -> 43.19 | L36: =IFERROR(AVERAGEIF('Реестр уборки 2025'!Z:Z,'Данные 2025'!J36,'Реестр уборки 2025'!C:C),) -> 48 | M36: 40-52
A37: Собственное сырье | B37: =F12 -> 7098.14 | I37: 34 | J37: 45837 | K37: =SUMIF('Реестр уборки 2025'!Z:Z,J37,'Реестр уборки 2025'!G:G)/1000 -> 71.97 | L37: =IFERROR(AVERAGEIF('Реестр уборки 2025'!Z:Z,'Данные 2025'!J37,'Реестр уборки 2025'!C:C),) -> 48.444444 | M37: 40-52
A38: Закупка | B38: 0 | C38: не указана закупка Брактовского, так как она была запланирована в конвейере | I38: 35 | J38: 45838 | K38: =SUMIF('Реестр уборки 2025'!Z:Z,J38,'Реестр уборки 2025'!G:G)/1000 -> 25.63 | L38: =IFERROR(AVERAGEIF('Реестр уборки 2025'!Z:Z,'Данные 2025'!J38,'Реестр уборки 2025'!C:C),) -> 52 | M38: 40-52
I39: 36 | J39: 45839 | K39: =SUMIF('Реестр уборки 2025'!Z:Z,J39,'Реестр уборки 2025'!G:G)/1000 -> 176.53 | L39: =IFERROR(AVERAGEIF('Реестр уборки 2025'!Z:Z,'Данные 2025'!J39,'Реестр уборки 2025'!C:C),) -> 54 | M39: 53-63
I40: 37 | J40: 45840 | K40: =SUMIF('Реестр уборки 2025'!Z:Z,J40,'Реестр уборки 2025'!G:G)/1000 -> 192.78 | L40: =IFERROR(AVERAGEIF('Реестр уборки 2025'!Z:Z,'Данные 2025'!J40,'Реестр уборки 2025'!C:C),) -> 52.357143 | M40: 40-52
I41: 38 | J41: 45841 | K41: =SUMIF('Реестр уборки 2025'!Z:Z,J41,'Реестр уборки 2025'!G:G)/1000 -> 204.08 | L41: =IFERROR(AVERAGEIF('Реестр уборки 2025'!Z:Z,'Данные 2025'!J41,'Реестр уборки 2025'!C:C),) -> 55.6875 | M41: 53-63
...

Sheet СВОД по полям
A1: Контрагент | B1: Полив | C1: Номер поля | D1: Сорт | E1: Площадь сева | F1: Площадь уборки | G1: Остаток площади | H1: Закрытие, % | I1: Урожайность плановая, т/га | J1: Урожайность фактическая, т/га | K1: Валовый сбор плановый, т | L1: Валовый сбор фактический, т | M1: Выполнение плана, %
A2: ООО ГРК | B2: богара | C2: А-17 | D2: Преладо | E2: 48 | F2: =#VALUE! -> #VALUE! | G2: =E2-F2 -> #VALUE! | H2: =IFERROR(F2/E2,"-") -> - | I2: =4*0.9 -> 3.6 | J2: =IFERROR(L2/F2,) -> 0 | K2: =E2*I2 -> 172.8 | L2: =#VALUE! -> #VALUE! | M2: =IFERROR(L2/K2,"-") -> -

Sheet Поступление на завод 
A1: Продажа | B1: (пусто)
E3: Данные
A4: Регистратор.Дата | B4: Культура | C4: Поле | D4: Регистратор.Номенклатура | E4: Физический вес, кг | F4: Зачетный вес, кг
A5: (пусто) | B5: ГРК (богара) | E5: 1297240 | F5: 1056094.5
A6: Итог Результат | E6: 1297240 | F6: 1056094.5

Sheet Поступление на завод по дням
A3: Дата | B3: Физический вес, тонны | C3: Физический вес, кг | D3: Зачетный вес, кг | E3: Дата акта входного контроля | I3: По дате акта входного контроля
A4: 45804 | B4: =C4/1000 -> 29.45 | C4: 29450 | D4: 21740.7 | E4: 45804 | I4: Физический вес, тонны
A5: 45805 | B5: =C5/1000 -> 98.79 | C5: 98790 | D5: 71595.6 | E5: 45805 | I5: 6485.45
A6: 45806 | B6: =C6/1000 -> 52.63 | C6: 52630 | D6: 37492 | E6: 45806
A7: 45807 | B7: =C7/1000 -> 46.31 | C7: 46310 | D7: 33701.5 | E7: 45808
A8: 45808
A9: 45809 | B9: =C9/1000 -> 163.7 | C9: 163700 | D9: 124140.6 | E9: 45809
A10: 45810 | B10: =C10/1000 -> 181.62 | C10: 181620 | D10: 141581.7 | E10: 45810
A11: 45811 | B11: =C11/1000 -> 137.38 | C11: 137380 | D11: 111232.3 | E11: 45811
A12: 45812 | B12: =C12/1000 -> 218.34 | C12: 218340 | D12: 186899.6 | E12: 45812
A13: 45813 | B13: =C13/1000 -> 257.7 | C13: 257700 | D13: 215785.7 | E13: 45813
A14: 45814 | B14: =C14/1000 -> 187.54 | C14: 187540 | D14: 157412.6 | E14: 45814
A15: 45815 | B15: =C15/1000 -> 222.75 | C15: 222750 | D15: 189231 | E15: 45815
A16: 45816 | B16: =C16/1000 -> 244.84 | C16: 244840 | D16: 214198.4 | E16: 45816
A17: 45817 | B17: =C17/1000 -> 152.51 | C17: 152510 | D17: 127138.9 | E17: 45817
A18: 45818 | B18: =C18/1000 -> 185.62 | C18: 185620 | D18: 159943.4 | E18: 45818
A19: 45819 | B19: =C19/1000 -> 159.63 | C19: 159630 | D19: 146763.8 | E19: 45819
A20: 45820 | B20: =C20/1000 -> 269.58 | C20: 269580 | D20: 233118.8 | E20: 45820
... A33: 45833 | B33: =C33/1000 -> 125.43 | C33: 125430 | D33: 104544.2 | E33: 45833
A34: 45834
A35: 45835
A36: 45836 | B36: =C36/1000 -> 60.75 | C36: 60750 | D36: 51333.9 | E36: 45836
A37: 45837 | B37: =C37/1000 -> 69.23 | C37: 69230 | D37: 60600.6 | E37: 45837
A38: 45838 | B38: =C38/1000 -> 28.37 | C38: 28370 | D38: 24692.3 | E38: 45838
A39: 45839 | B39: =C39/1000 -> 69.19 | C39: 69190 | D39: 60335.2 | E39: 45839
A40: 45840 | B40: =C40/1000 -> 218.92 | C40: 218920 | D40: 187414.8 | E40: 45840
A41: 45841 | B41: =C41/1000 -> 192.37 | C41: 192370 | D41: 161740.5 | E41: 45841
A42: 45842 | B42: =C42/1000 -> 213.73 | C42: 213730 | D42: 190148.5 | E42: 45842
A43: 45843 | B43: =C43/1000 -> 84.68 | C43: 84680 | D43: 73460.3 | E43: 45843
A44: 45844 | B44: =C44/1000 -> 226.12 | C44: 226120 | D44: 203439.1 | E44: 45844
A45: 45845
A46: 45846 | B46: =C46/1000 -> 40.51 | C46: 40510 | D46: 36604.8 | E46: 45846
A47: 45847 | B47: =C47/1000 -> 143.24 | C47: 143240 | D47: 125850.3 | E47: 45847
A48: 45848 | B48: =C48/1000 -> 38.47 | C48: 38470 | D48: 31337.5 | E48: 45848

Sheet по дням
A1: Продажа | B1: - все -
A3: Регистратор.Дата

Sheet Реестр уборки 2026
A1: Показатель | B1: Количество | C1: Значение финометра | D1: Регистратор.Номер | E1: Регистратор.Дата | F1: Регистратор.Вес брутто | G1: Регистратор.Вес нетто | H1: Регистратор.Вес тары | I1: Регистратор.Вес чистый | J1: Регистратор.Контрагент | K1: Регистратор.Номенклатура | L1: Регистратор.Комбайнеры.Поле.Наименование | M1: Регистратор.Водитель | N1: Регистратор.Время прибытия | O1: Регистратор.Время убытия | P1: Регистратор.Комбайнеры.Комбайнер.Наименование | Q1: Регистратор.Номера талонов | R1: Регистратор.Номер машины | S1: Регистратор.Номер прицепа | T1: Поле | U1: Сорт уточн | V1: Площадь уборки, га | W1: Культура | X1: Орошение | Y1: Смена | Z1: Дата отчета | AA1: Продажа | AB1: Примечание | AC1: Финометр | AD1: Характеристика | AE1: № акта | AF1: Дата акта | AG1: Вх № | AH1: Степень зрелости вспом
A2: Степень зрелости | C2: =Таблица3[[#This Row],[Степень зрелости вспом]] -> 49 | D2: 40 | G2: 16070 | I2: 12936.4 | J2: ГРИН РЭЙ КУБАНЬ ООО | K2: Тиара | M2: Богучарский А. И. | R2: А718ВХ | T2: А-4/1 | U2: =Таблица3[[#This Row],[Регистратор.Номенклатура]] -> Тиара | V2: =36*Таблица3[[#This Row],[Регистратор.Вес нетто]]/191510 -> 3.0208344 | W2: ГРК (богара) | X2: богара | Y2: 1 | Z2: 46176 | AC2: 40-52 | AD2: Высший | AE2: 14 | AF2: 46176 | AH2: =IFERROR(VLOOKUP(Таблица3[[#This Row],[№ акта]],'Степень зрелости 2026'!$H$12:$I$582,2,FALSE()),) -> 49
A3: Степень зрелости | C3: =Таблица3[[#This Row],[Степень зрелости вспом]] -> 53 | D3: 42 | G3: 13670 | I3: 9637.4 | J3: ГРИН РЭЙ КУБАНЬ ООО | K3: Тиара | M3: Сероштан Станислав Викторович | R3: Е758РЕ | T3: А-4/1 | U3: =Таблица3[[#This Row],[Регистратор.Номенклатура]] -> Тиара | V3: =36*Таблица3[[#This Row],[Регистратор.Вес нетто]]/191510 -> 2.569683 | W3: ГРК (богара) | X3: богара | Y3: 1 | Z3: 46176 | AC3: 53-63 | AD3: Высший | AE3: 15 | AF3: 46176 | AH3: =IFERROR(VLOOKUP(Таблица3[[#This Row],[№ акта]],'Степень зрелости 2026'!$H$12:$I$582,2,FALSE()),) -> 53
A4: Степень зрелости | C4: =Таблица3[[#This Row],[Степень зрелости вспом]] -> 50 | D4: 43 | G4: 13610 | I4: 10683.9 | J4: ГРИН РЭЙ КУБАНЬ ООО | K4: Тиара | M4: Богучарский А. И. | R4: А718ВХ | T4: А-4/1 | U4: =Таблица3[[#This Row],[Регистратор.Номенклатура]] -> Тиара | V4: =36*Таблица3[[#This Row],[Регистратор.Вес нетто]]/191510 -> 2.5584043 | W4: ГРК (богара) | X4: богара | Y4: 1 | Z4: 46176 | AC4: 40-52 | AD4: Высший | AE4: 16 | AF4: 46176 | AH4: =IFERROR(VLOOKUP(Таблица3[[#This Row],[№ акта]],'Степень зрелости 2026'!$H$12:$I$582,2,FALSE()),) -> 50
A5: Степень зрелости | C5: =Таблица3[[#This Row],[Степень зрелости вспом]] -> 54 | D5: 48 | G5: 13740 | I5: 10648.5 | J5: ГРИН РЭЙ КУБАНЬ ООО | K5: Тиара | M5: Кудря Евгений | R5: А719ОО | T5: А-4/1 | U5: =Таблица3[[#This Row],[Регистратор.Номенклатура]] -> Тиара | V5: =36*Таблица3[[#This Row],[Регистратор.Вес нетто]]/191510 -> 2.5828416 | W5: ГРК (богара) | X5: богара | Y5: 1 | Z5: 46176 | AC5: 53-63 | AD5: Высший | AE5: 17 | AF5: 46176 | AH5: =IFERROR(VLOOKUP(Таблица3[[#This Row],[№ акта]],'Степень зрелости 2026'!$H$12:$I$582,2,FALSE()),) -> 54
A6: Степень зрелости | C6: =Таблица3[[#This Row],[Степень зрелости вспом]] -> 53 | D6: 49 | G6: 13660 | I6: 10996.3 | J6: ГРИН РЭЙ КУБАНЬ ООО | K6: Тиара | M6: Богучарский А. И. | R6: А718ВХ | T6: А-4/1 | U6: =Таблица3[[#This Row],[Регистратор.Номенклатура]] -> Тиара | V6: =36*Таблица3[[#This Row],[Регистратор.Вес нетто]]/191510 -> 2.5678032 | W6: ГРК (богара) | X6: богара | Y6: 1 | Z6: 46176 | AC6: 53-63 | AD6: Высший | AE6: 18 | AF6: 46176 | AH6: =IFERROR(VLOOKUP(Таблица3[[#This Row],[№ акта]],'Степень зрелости 2026'!$H$12:$I$582,2,FALSE()),) -> 53
A7: Степень зрелости | C7: =Таблица3[[#This Row],[Степень зрелости вспом]] -> 53 | D7: 50 | G7: 13390 | I7: 10645.1 | J7: ГРИН РЭЙ КУБАНЬ ООО | K7: Тиара | M7: Черевко Александр Владимирович | R7: А114МК | T7: А-4/1 | U7: =Таблица3[[#This Row],[Регистратор.Номенклатура]] -> Тиара | V7: =36*Таблица3[[#This Row],[Регистратор.Вес нетто]]/191510 -> 2.5170487 | W7: ГРК (богара) | X7: богара | Y7: 1 | Z7: 46176 | AC7: 53-63 | AD7: Высший | AE7: 19 | AF7: 46176 | AH7: =IFERROR(VLOOKUP(Таблица3[[#This Row],[№ акта]],'Степень зрелости 2026'!$H$12:$I$582,2,FALSE()),) -> 53
A8: Степень зрелости | C8: =Таблица3[[#This Row],[Степень зрелости вспом]] -> 52 | D8: 51 | G8: 13720 | I8: 10907.4 | J8: ГРИН РЭЙ КУБАНЬ ООО | K8: Тиара | M8: Кудря Евгений | R8: А719ОО | T8: А-4/1 | U8: =Таблица3[[#This Row],[Регистратор.Номенклатура]] -> Тиара | V8: =36*Таблица3[[#This Row],[Регистратор.Вес нетто]]/191510 -> 2.579082 | W8: ГРК (богара) | X8: богара | Y8: 1 | Z8: 46176 | AC8: 40-52 | AD8: Высший | AE8: 20 | AF8: 46176 | AH8: =IFERROR(VLOOKUP(Таблица3[[#This Row],[№ акта]],'Степень зрелости 2026'!$H$12:$I$582,2,FALSE()),) -> 52
A9: Степень зрелости | C9: =Таблица3[[#This Row],[Степень зрелости вспом]] -> 52 | D9: 52 | G9: 13740 | I9: 11060.7 | J9: ГРИН РЭЙ КУБАНЬ ООО | K9: Тиара | M9: Богучарский А. И. | R9: А718ВХ | T9: А-4/1 | U9: =Таблица3[[#This Row],[Регистратор.Номенклатура]] -> Тиара | V9: =36*Таблица3[[#This Row],[Регистратор.Вес нетто]]/191510 -> 2.5828416 | W9: ГРК (богара) | X9: богара | Y9: 1 | Z9: 46176 | AC9: 40-52 | AD9: Высший | AE9: 21 | AF9: 46176 | AH9: =IFERROR(VLOOKUP(Таблица3[[#This Row],[№ акта]],'Степень зрелости 2026'!$H$12:$I$582,2,FALSE()),) -> 52
A10: Степень зрелости | C10: =Таблица3[[#This Row],[Степень зрелости вспом]] -> 51 | D10: 53 | G10: 13260 | I10: 10674.3 | J10: ГРИН РЭЙ КУБАНЬ ООО | K10: Тиара | M10: Черевко Александр Владимирович | R10: А114МК | T10: А-4/1 | U10: =Таблица3[[#This Row],[Регистратор.Номенклатура]] -> Тиара | V10: =36*Таблица3[[#This Row],[Регистратор.Вес нетто]]/191510 -> 2.4926114 | W10: ГРК (богара) | X10: богара | Y10: 1 | Z10: 46176 | AC10: 40-52 | AD10: Высший | AE10: 22 | AF10: 46177 | AH10: =IFERROR(VLOOKUP(Таблица3[[#This Row],[№ акта]],'Степень зрелости 2026'!$H$12:$I$582,2,FALSE()),) -> 51
A11: Степень зрелости | C11: =Таблица3[[#This Row],[Степень зрелости вспом]] -> 53 | D11: 54 | G11: 13390 | I11: 10779 | J11: ГРИН РЭЙ КУБАНЬ ООО | K11: Тиара | M11: Кудря Евгений | R11: А719ОО | T11: А-4/1 | U11: =Таблица3[[#This Row],[Регистратор.Номенклатура]] -> Тиара | V11: =36*Таблица3[[#This Row],[Регистратор.Вес нетто]]/191510 -> 2.5170487 | W11: ГРК (богара) | X11: богара | Y11: 1 | Z11: 46176 | AC11: 53-63 | AD11: Высший | AE11: 23 | AF11: 46177 | AH11: =IFERROR(VLOOKUP(Таблица3[[#This Row],[№ акта]],'Степень зрелости 2026'!$H$12:$I$582,2,FALSE()),) -> 53
A12: Степень зрелости | C12: =Таблица3[[#This Row],[Степень зрелости вспом]] -> 55 | D12: 55 | G12: 13270 | I12: 10815.1 | J12: ГРИН РЭЙ КУБАНЬ ООО | K12: Тиара | M12: Богучарский А. И. | R12: А718ВХ | T12: А-4/1 | U12: =Таблица3[[#This Row],[Регистратор.Номенклатура]] -> Тиара | V12: =36*Таблица3[[#This Row],[Регистратор.Вес нетто]]/191510 -> 2.4944911 | W12: ГРК (богара) | X12: богара | Y12: 1 | Z12: 46176 | AC12: 53-63 | AD12: Высший | AE12: 24 | AF12: 46177 | AH12: =IFERROR(VLOOKUP(Таблица3[[#This Row],[№ акта]],'Степень зрелости 2026'!$H$12:$I$582,2,FALSE()),) -> 55
A13: Степень зрелости | C13: =Таблица3[[#This Row],[Степень зрелости вспом]] -> 50 | D13: 56 | G13: 13200 | I13: 10362 | J13: ГРИН РЭЙ КУБАНЬ ООО | K13: Тиара | M13: Черевко Александр Владимирович | R13: А114МК | T13: А-4/1 | U13: =Таблица3[[#This Row],[Регистратор.Номенклатура]] -> Тиара | V13: =36*Таблица3[[#This Row],[Регистратор.Вес нетто]]/191510 -> 2.4813326 | W13: ГРК (богара) | X13: богара | Y13: 1 | Z13: 46176 | AC13: 40-52 | AD13: Высший | AE13: 25 | AF13: 46177 | AH13: =IFERROR(VLOOKUP(Таблица3[[#This Row],[№ акта]],'Степень зрелости 2026'!$H$12:$I$582,2,FALSE()),) -> 50
... A15: Степень зрелости | C15: =Таблица3[[#This Row],[Степень зрелости вспом]] -> 54 | D15: 59 | G15: 13760 | I15: 10939.2 | J15: ГРИН РЭЙ КУБАНЬ ООО | K15: Тиара | M15: Погуляй А.Б. | R15: К403ЕМ | T15: А-4/1 | U15: =Таблица3[[#This Row],[Регистратор.Номенклатура]] -> Тиара | V15: =36*Таблица3[[#This Row],[Регистратор.Вес нетто]]/191510 -> 2.5866012 | W15: ГРК (богара) | X15: богара | Y15: 1 | Z15: 46176 | AC15: 53-63 | AD15: Высший | AE15: 27 | AF15: 46177 | AH15: =IFERROR(VLOOKUP(Таблица3[[#This Row],[№ акта]],'Степень зрелости 2026'!$H$12:$I$582,2,FALSE()),) -> 54
C16: =Таблица3[[#This Row],[Степень зрелости вспом]] -> 55 | D16: 61 | G16: 13570 | I16: 10516.7 | J16: ГРИН РЭЙ КУБАНЬ ООО | K16: Тиара | M16: Деревянко Н.Н. | R16: Р699ОН | T16: А-4/1 | U16: =Таблица3[[#This Row],[Регистратор.Номенклатура]] -> Тиара | V16: =20*Таблица3[[#This Row],[Регистратор.Вес нетто]]/111250 -> 2.4395506 | W16: ГРК (богара) | X16: богара | Y16: 2 | Z16: 46177 | AC16: 53-63 | AD16: Высший | AE16: 28 | AF16: 46177 | AH16: =IFERROR(VLOOKUP(Таблица3[[#This Row],[№ акта]],'Степень зрелости 2026'!$H$12:$I$582,2,FALSE()),) -> 55
C17: =Таблица3[[#This Row],[Степень зрелости вспом]] -> 55 | D17: 63 | G17: 13280 | I17: 10823.2 | J17: ГРИН РЭЙ КУБАНЬ ООО | K17: Тиара | M17: Осипов Александр Николаевич | R17: Е732УС | T17: А-4/1 | U17: =Таблица3[[#This Row],[Регистратор.Номенклатура]] -> Тиара | V17: =20*Таблица3[[#This Row],[Регистратор.Вес нетто]]/111250 -> 2.3874157 | W17: ГРК (богара) | X17: богара | Y17: 2 | Z17: 46177 | AC17: 53-63 | AD17: Высший | AE17: 29 | AF17: 46177 | AH17: =IFERROR(VLOOKUP(Таблица3[[#This Row],[№ акта]],'Степень зрелости 2026'!$H$12:$I$582,2,FALSE()),) -> 55
C18: =Таблица3[[#This Row],[Степень зрелости вспом]] -> 53 | D18: 64 | G18: 13840 | I18: 11418 | J18: ГРИН РЭЙ КУБАНЬ ООО | K18: Тиара | M18: Бербеницкий Сергей Николаевич | R18: С400РР | T18: А-4/1 | U18: =Таблица3[[#This Row],[Регистратор.Номенклатура]] -> Тиара | V18: =20*Таблица3[[#This Row],[Регистратор.Вес нетто]]/111250 -> 2.4880899 | W18: ГРК (богара) | X18: богара | Y18: 2 | Z18: 46177 | AC18: 53-63 | AD18: Высший | AE18: 30 | AF18: 46177 | AH18: =IFERROR(VLOOKUP(Таблица3[[#This Row],[№ акта]],'Степень зрелости 2026'!$H$12:$I$582,2,FALSE()),) -> 53
C19: =Таблица3[[#This Row],[Степень зрелости вспом]] -> 53 | D19: 65 | G19: 14080 | I19: 11334.4 | J19: ГРИН РЭЙ КУБАНЬ ООО | K19: Тиара | M19: Погуляй А.Б. | R19: К403ЕМ | T19: А-4/1 | U19: =Таблица3[[#This Row],[Регистратор.Номенклатура]] -> Тиара | V19: =20*Таблица3[[#This Row],[Регистратор.Вес нетто]]/111250 -> 2.531236 | W19: ГРК (богара) | X19: богара | Y19: 2 | Z19: 46177 | AC19: 53-63 | AD19: Высший | AE19: 31 | AF19: 46177 | AH19: =IFERROR(VLOOKUP(Таблица3[[#This Row],[№ акта]],'Степень зрелости 2026'!$H$12:$I$582,2,FALSE()),) -> 53
C20: =Таблица3[[#This Row],[Степень зрелости вспом]] -> 52 | D20: 66 | G20: 14070 | I20: 11467.1 | J20: ГРИН РЭЙ КУБАНЬ ООО | K20: Тиара | M20: Деревянко Н.Н. | R20: Р699ОН | T20: А-4/1 | U20: =Таблица3[[#This Row],[Регистратор.Номенклатура]] -> Тиара | V20: =20*Таблица3[[#This Row],[Регистратор.Вес нетто]]/111250 -> 2.5294382 | W20: ГРК (богара) | X20: богара | Y20: 2 | Z20: 46177 | AC20: 40-52 | AD20: Высший | AE20: 32 | AF20: 46177 | AH20: =IFERROR(VLOOKUP(Таблица3[[#This Row],[№ акта]],'Степень зрелости 2026'!$H$12:$I$582,2,FALSE()),) -> 52
C21: =Таблица3[[#This Row],[Степень зрелости вспом]] -> 53 | D21: 68 | G21: 14230 | I21: 11739.8 | J21: ГРИН РЭЙ КУБАНЬ ООО | K21: Тиара | M21: Ревенко Андрей Вячеславович | R21: А781РР | T21: А-4/1 | U21: =Таблица3[[#This Row],[Регистратор.Номенклатура]] -> Тиара | V21: =20*Таблица3[[#This Row],[Регистратор.Вес нетто]]/111250 -> 2.5582022 | W21: ГРК (богара) | X21: богара | Y21: 2 | Z21: 46177 | AC21: 53-63 | AD21: Высший | AE21: 33 | AF21: 46177 | AH21: =IFERROR(VLOOKUP(Таблица3[[#This Row],[№ акта]],'Степень зрелости 2026'!$H$12:$I$582,2,FALSE()),) -> 53
C22: =Таблица3[[#This Row],[Степень зрелости вспом]] -> 53 | D22: 70 | G22: 14110 | I22: 11781.8 | J22: ГРИН РЭЙ КУБАНЬ ООО | K22: Тиара | M22: Погуляй А.Б. | R22: К403ЕМ | T22: А-4/1 | U22: =Таблица3[[#This Row],[Регистратор.Номенклатура]] -> Тиара | V22: =20*Таблица3[[#This Row],[Регистратор.Вес нетто]]/111250 -> 2.5366292 | W22: ГРК (богара) | X22: богара | Y22: 2 | Z22: 46177 | AC22: 53-63 | AD22: Высший | AE22: 35 | AF22: 46177 | AH22: =IFERROR(VLOOKUP(Таблица3[[#This Row],[№ акта]],'Степень зрелости 2026'!$H$12:$I$582,2,FALSE()),) -> 53
C23: =Таблица3[[#This Row],[Степень зрелости вспом]] -> 52 | D23: 69 | G23: 14070 | I23: 11185.7 | J23: ГРИН РЭЙ КУБАНЬ ООО | K23: Тиара | M23: Бербеницкий Сергей Николаевич | R23: С400РР | T23: А-4/1 | U23: =Таблица3[[#This Row],[Регистратор.Номенклатура]] -> Тиара | V23: =20*Таблица3[[#This Row],[Регистратор.Вес нетто]]/111250 -> 2.5294382 | W23: ГРК (богара) | X23: богара | Y23: 2 | Z23: 46177 | AC23: 40-52 | AD23: Высший | AE23: 34 | AF23: 46177 | AH23: =IFERROR(VLOOKUP(Таблица3[[#This Row],[№ акта]],'Степень зрелости 2026'!$H$12:$I$582,2,FALSE()),) -> 52
C24: =Таблица3[[#This Row],[Степень зрелости вспом]] -> 42 | D24: 71 | G24: 6120 | I24: 4039.2 | J24: ГРИН РЭЙ КУБАНЬ ООО | K24: Авола | M24: Деревянко Н.Н. | R24: Р699ОН | T24: А-3 | U24: =Таблица3[[#This Row],[Регистратор.Номенклатура]] -> Авола | V24: =2*Таблица3[[#This Row],[Регистратор.Вес нетто]]/6120 -> 2 | W24: ГРК (богара) | X24: богара | Y24: 2 | Z24: 46177 | AC24: 40-52 | AD24: Высший | AE24: 36 | AF24: 46177 | AH24: =IFERROR(VLOOKUP(Таблица3[[#This Row],[№ акта]],'Степень зрелости 2026'!$H$12:$I$582,2,FALSE()),) -> 42
C25: =Таблица3[[#This Row],[Степень зрелости вспом]] -> 49 | D25: 95 | G25: 15500 | I25: 12322.5 | J25: ГРИН РЭЙ КУБАНЬ ООО | K25: Тиара | M25: Погуляй А.Б. | R25: О824ТХ | T25: А-4/1 | U25: =Таблица3[[#This Row],[Регистратор.Номенклатура]] -> Тиара | V25: =42*Таблица3[[#This Row],[Регистратор.Вес нетто]]/244270 -> 2.6650837 | W25: ГРК (богара) | X25: богара | Y25: 3 | Z25: 46179 | AC25: 40-52 | AD25: Высший | AE25: 51 | AF25: 46179 | AH25: =IFERROR(VLOOKUP(Таблица3[[#This Row],[№ акта]],'Степень зрелости 2026'!$H$12:$I$582,2,FALSE()),) -> 49
C26: =Таблица3[[#This Row],[Степень зрелости вспом]] -> 49 | D26: 96 | G26: 13520 | I26: 10342.8 | J26: ГРИН РЭЙ КУБАНЬ ООО | K26: Тиара | M26: Деревянко Н.Н. | R26: Р699ОН | T26: А-4/1 | U26: =Таблица3[[#This Row],[Регистратор.Номенклатура]] -> Тиара | V26: =42*Таблица3[[#This Row],[Регистратор.Вес нетто]]/244270 -> 2.3246408 | W26: ГРК (богара) | X26: богара | Y26: 3 | Z26: 46179 | AC26: 40-52 | AD26: Высший | AE26: 52 | AF26: 46179 | AH26: =IFERROR(VLOOKUP(Таблица3[[#This Row],[№ акта]],'Степень зрелости 2026'!$H$12:$I$582,2,FALSE()),) -> 49
C27: =Таблица3[[#This Row],[Степень зрелости вспом]] -> 48 | D27: 97 | G27: 13550 | I27: 10772.3 | J27: ГРИН РЭЙ КУБАНЬ ООО | K27: Тиара | M27: Бербеницкий Сергей Николаевич | R27: С400РР | T27: А-4/1 | U27: =Таблица3[[#This Row],[Регистратор.Номенклатура]] -> Тиара | V27: =42*Таблица3[[#This Row],[Регистратор.Вес нетто]]/244270 -> 2.329799 | W27: ГРК (богара) | X27: богара | Y27: 3 | Z27: 46179 | AC27: 40-52 | AD27: Высший | AE27: 53 | AF27: 46179 | AH27: =IFERROR(VLOOKUP(Таблица3[[#This Row],[№ акта]],'Степень зрелости 2026'!$H$12:$I$582,2,FALSE()),) -> 48
C28: =Таблица3[[#This Row],[Степень зрелости вспом]] -> 47 | D28: 98 | G28: 4470 | I28: 3687.7 | J28: ГРИН РЭЙ КУБАНЬ ООО | K28: Тиара | M28: Сайко Владимир Николаевич | R28: Т919РВ | T28: А-4/1 | U28: =Таблица3[[#This Row],[Регистратор.Номенклатура]] -> Тиара | V28: =42*Таблица3[[#This Row],[Регистратор.Вес нетто]]/244270 -> 0.76857576 | W28: ГРК (богара) | X28: богара | Y28: 3 | Z28: 46179 | AC28: 40-52 | AD28: Высший | AE28: 54 | AF28: 46179 | AH28: =IFERROR(VLOOKUP(Таблица3[[#This Row],[№ акта]],'Степень зрелости 2026'!$H$12:$I$582,2,FALSE()),) -> 47
C29: =Таблица3[[#This Row],[Степень зрелости вспом]] -> 50 | D29: 76 | G29: 15750 | I29: 13308.8 | J29: ГРИН РЭЙ КУБАНЬ ООО | K29: Тиара | M29: Бербеницкий Сергей Николаевич | R29: С400РР | T29: А-22/1 | U29: =Таблица3[[#This Row],[Регистратор.Номенклатура]] -> Тиара | V29: =5*Таблица3[[#This Row],[Регистратор.Вес нетто]]/24650 -> 3.1947262 | W29: ГРК (богара) | X29: богара | Y29: 3 | Z29: 46179 | AC29: 40-52 | AD29: Высший | AE29: 41 | AF29: 46179 | AH29: =IFERROR(VLOOKUP(Таблица3[[#This Row],[№ акта]],'Степень зрелости 2026'!$H$12:$I$582,2,FALSE()),) -> 50
C30: =Таблица3[[#This Row],[Степень зрелости вспом]] -> 54 | D30: 77 | G30: 8900 | I30: 7609.5 | J30: ГРИН РЭЙ КУБАНЬ ООО | K30: Тиара | M30: Чигрин Н.А. | R30: А819ЕВ | T30: А-22/1 | U30: =Таблица3[[#This Row],[Регистратор.Номенклатура]] -> Тиара | V30: =5*Таблица3[[#This Row],[Регистратор.Вес нетто]]/24650 -> 1.8052738 | W30: ГРК (богара) | X30: богара | Y30: 3 | Z30: 46179 | AC30: 53-63 | AD30: Высший | AE30: 37 | AF30: 46179 | AH30: =IFERROR(VLOOKUP(Таблица3[[#This Row],[№ акта]],'Степень зрелости 2026'!$H$12:$I$582,2,FALSE()),) -> 54
C31: =Таблица3[[#This Row],[Степень зрелости вспом]] -> 46 | D31: 84 | G31: 4550 | I31: 3617.2 | J31: ГРИН РЭЙ КУБАНЬ ООО | K31: Тиара | M31: Сайко Владимир Николаевич | R31: Т919РВ | T31: А-4/1 | U31: =Таблица3[[#This Row],[Регистратор.Номенклатура]] -> Тиара | V31: =42*Таблица3[[#This Row],[Регистратор.Вес нетто]]/244270 -> 0.78233103 | W31: ГРК (богара) | X31: богара | Y31: 3 | Z31: 46179 | AC31: 40-52 | AD31: Высший | AE31: 42 | AF31: 46179 | AH31: =IFERROR(VLOOKUP(Таблица3[[#This Row],[№ акта]],'Степень зрелости 2026'!$H$12:$I$582,2,FALSE()),) -> 46
C32: =Таблица3[[#This Row],[Степень зрелости вспом]] -> 47 | D32: 85 | G32: 13630 | I32: 10835.8 | J32: ГРИН РЭЙ КУБАНЬ ООО | K32: Тиара | M32: Погуляй А.Б. | R32: О824ТХ | T32: А-4/1 | U32: =Таблица3[[#This Row],[Регистратор.Номенклатура]] -> Тиара | V32: =42*Таблица3[[#This Row],[Регистратор.Вес нетто]]/244270 -> 2.3435543 | W32: ГРК (богара) | X32: богара | Y32: 3 | Z32: 46179 | AC32: 40-52 | AD32: Высший | AE32: 43 | AF32: 46179 | AH32: =IFERROR(VLOOKUP(Таблица3[[#This Row],[№ акта]],'Степень зрелости 2026'!$H$12:$I$582,2,FALSE()),) -> 47
C33: =Таблица3[[#This Row],[Степень зрелости вспом]] -> 47 | D33: 86 | G33: 13840 | I33: 10726 | J33: ГРИН РЭЙ КУБАНЬ ООО | K33: Тиара | M33: Деревянко Н.Н. | R33: Р699ОН | T33: А-4/1 | U33: =Таблица3[[#This Row],[Регистратор.Номенклатура]] -> Тиара | V33: =42*Таблица3[[#This Row],[Регистратор.Вес нетто]]/244270 -> 2.3796618 | W33: ГРК (богара) | X33: богара | Y33: 3 | Z33: 46179 | AC33: 40-52 | AD33: Высший | AE33: 44 | AF33: 46179 | AH33: =IFERROR(VLOOKUP(Таблица3[[#This Row],[№ акта]],'Степень зрелости 2026'!$H$12:$I$582,2,FALSE()),) -> 47
C34: =Таблица3[[#This Row],[Степень зрелости вспом]] -> 44 | D34: 87 | G34: 13640 | I34: 10707.4 | J34: ГРИН РЭЙ КУБАНЬ ООО | K34: Тиара | M34: Бербеницкий Сергей Николаевич | R34: С400РР | T34: А-4/1 | U34: =Таблица3[[#This Row],[Регистратор.Номенклатура]] -> Тиара | V34: =42*Таблица3[[#This Row],[Регистратор.Вес нетто]]/244270 -> 2.3452737 | W34: ГРК (богара) | X34: богара | Y34: 3 | Z34: 46179 | AC34: 40-52 | AD34: Высший | AE34: 45 | AF34: 46179 | AH34: =IFERROR(VLOOKUP(Таблица3[[#This Row],[№ акта]],'Степень зрелости 2026'!$H$12:$I$582,2,FALSE()),) -> 44
C35: =Таблица3[[#This Row],[Степень зрелости вспом]] -> 43 | D35: 88 | G35: 4660 | I35: 3658.1 | J35: ГРИН РЭЙ КУБАНЬ ООО | K35: Тиара | M35: Сайко Владимир Николаевич | R35: Т919РВ | T35: А-4/1 | U35: =Таблица3[[#This Row],[Регистратор.Номенклатура]] -> Тиара | V35: =42*Таблица3[[#This Row],[Регистратор.Вес нетто]]/244270 -> 0.80124452 | W35: ГРК (богара) | X35: богара | Y35: 3 | Z35: 46179 | AC35: 40-52 | AD35: Высший | AE35: 46 | AF35: 46179 | AH35: =IFERROR(VLOOKUP(Таблица3[[#This Row],[№ акта]],'Степень зрелости 2026'!$H$12:$I$582,2,FALSE()),) -> 43
C36: =Таблица3[[#This Row],[Степень зрелости вспом]] -> 47 | D36: 89 | G36: 13710 | I36: 10762.4 | J36: ГРИН РЭЙ КУБАНЬ ООО | K36: Тиара | M36: Чигрин Н.А. | R36: А819ЕВ | T36: А-4/1 | U36: =Таблица3[[#This Row],[Регистратор.Номенклатура]] -> Тиара | V36: =42*Таблица3[[#This Row],[Регистратор.Вес нетто]]/244270 -> 2.3573095 | W36: ГРК (богара) | X36: богара | Y36: 3 | Z36: 46179 | AC36: 40-52 | AD36: Высший | AE36: 47 | AF36: 46179 | AH36: =IFERROR(VLOOKUP(Таблица3[[#This Row],[№ акта]],'Степень зрелости 2026'!$H$12:$I$582,2,FALSE()),) -> 47
C37: =Таблица3[[#This Row],[Степень зрелости вспом]] -> 45 | D37: 90 | G37: 14310 | I37: 11233.3 | J37: ГРИН РЭЙ КУБАНЬ ООО | K37: Тиара | M37: Погуляй А.Б. | R37: О824ТХ | T37: А-4/1 | U37: =Таблица3[[#This Row],[Регистратор.Номенклатура]] -> Тиара | V37: =42*Таблица3[[#This Row],[Регистратор.Вес нетто]]/244270 -> 2.4604741 | W37: ГРК (богара) | X37: богара | Y37: 3 | Z37: 46179 | AC37: 40-52 | AD37: Высший | AE37: 48 | AF37: 46179 | AH37: =IFERROR(VLOOKUP(Таблица3[[#This Row],[№ акта]],'Степень зрелости 2026'!$H$12:$I$582,2,FALSE()),) -> 45
C38: =Таблица3[[#This Row],[Степень зрелости вспом]] -> 50 | D38: 91 | G38: 13690 | I38: 10472.9 | J38: ГРИН РЭЙ КУБАНЬ ООО | K38: Тиара | M38: Деревянко Н.Н. | R38: Р699ОН | T38: А-4/1 | U38: =Таблица3[[#This Row],[Регистратор.Номенклатура]] -> Тиара | V38: =42*Таблица3[[#This Row],[Регистратор.Вес нетто]]/244270 -> 2.3538707 | W38: ГРК (богара) | X38: богара | Y38: 3 | Z38: 46179 | AC38: 40-52 | AD38: Высший | AE38: 49 | AF38: 46179 | AH38: =IFERROR(VLOOKUP(Таблица3[[#This Row],[№ акта]],'Степень зрелости 2026'!$H$12:$I$582,2,FALSE()),) -> 50
C39: =Таблица3[[#This Row],[Степень зрелости вспом]] -> 50 | D39: 92 | G39: 13840 | I39: 11002.8 | J39: ГРИН РЭЙ КУБАНЬ ООО | K39: Тиара | M39: Бербеницкий Сергей Николаевич | R39: С400РР | T39: А-4/1 | U39: =Таблица3[[#This Row],[Регистратор.Номенклатура]] -> Тиара | V39: =42*Таблица3[[#This Row],[Регистратор.Вес нетто]]/244270 -> 2.3796618 | W39: ГРК (богара) | X39: богара | Y39: 3 | Z39: 46179 | AC39: 40-52 | AD39: Высший | AE39: 39 | AF39: 46179 | AH39: =IFERROR(VLOOKUP(Таблица3[[#This Row],[№ акта]],'Степень зрелости 2026'!$H$12:$I$582,2,FALSE()),) -> 50
C40: =Таблица3[[#This Row],[Степень зрелости вспом]] -> 53 | D40: 93 | G40: 13630 | I40: 11244.8 | J40: ГРИН РЭЙ КУБАНЬ ООО | K40: Тиара | M40: Чигрин Н.А. | R40: А819ЕВ | T40: А-4/1 | U40: =Таблица3[[#This Row],[Регистратор.Номенклатура]] -> Тиара | V40: =42*Таблица3[[#This Row],[Регистратор.Вес нетто]]/244270 -> 2.3435543 | W40: ГРК (богара) | X40: богара | Y40: 3 | Z40: 46179 | AC40: 53-63 | AD40: Высший | AE40: 38 | AF40: 46179 | AH40: =IFERROR(VLOOKUP(Таблица3[[#This Row],[№ акта]],'Степень зрелости 2026'!$H$12:$I$582,2,FALSE()),) -> 53
C41: =Таблица3[[#This Row],[Степень зрелости вспом]] -> 45 | D41: 94 | G41: 4690 | I41: 3728.5 | J41: ГРИН РЭЙ КУБАНЬ ООО | K41: Тиара | M41: Сайко Владимир Николаевич | R41: Т919РВ | T41: А-4/1 | U41: =Таблица3[[#This Row],[Регистратор.Номенклатура]] -> Тиара | V41: =42*Таблица3[[#This Row],[Регистратор.Вес нетто]]/244270 -> 0.80640275 | W41: ГРК (богара) | X41: богара | Y41: 3 | Z41: 46179 | AC41: 40-52 | AD41: Высший | AE41: 40 | AF41: 46179 | AH41: =IFERROR(VLOOKUP(Таблица3[[#This Row],[№ акта]],'Степень зрелости 2026'!$H$12:$I$582,2,FALSE()),) -> 45
...

Sheet Реестр уборки 2025
A1: Показатель | B1: Количество | C1: Значение финометра | D1: Регистратор.Номер | E1: Регистратор.Дата | F1: Регистратор.Вес брутто | G1: Регистратор.Вес нетто | H1: Регистратор.Вес тары | I1: Регистратор.Вес чистый | J1: Регистратор.Контрагент | K1: Регистратор.Номенклатура | L1: Регистратор.Комбайнеры.Поле.Наименование | M1: Регистратор.Водитель | N1: Регистратор.Время прибытия | O1: Регистратор.Время убытия | P1: Регистратор.Комбайнеры.Комбайнер.Наименование | Q1: Регистратор.Номера талонов | R1: Регистратор.Номер машины | S1: Регистратор.Номер прицепа | T1: Поле | U1: Сорт уточн | V1: Площадь уборки, га | W1: Культура | X1: Орошение | Y1: Смена | Z1: Дата отчета | AA1: Продажа | AB1: Примечание | AC1: Финометр | AD1: Характеристика | AE1: № акта | AF1: Дата акта | AG1: Вх № | AH1: Степень зрелости вспом | AI1: Поле до корр | AJ1: Сорт до корр | AK1: Культура до корр | AL1: Площадь уборки до корр | AM1: Отличие | AN1: Разница по площади | AP1: Из итогового отчета | AQ1: Акт | AR1: Поле | AS1: Площадь, га | AT1: Культура
A2: Степень зрелости | B2: 9803.9 | C2: 40 | D2: 44 | E2: 45804 | F2: 27380 | G2: 13430 | H2: 13950 | I2: 9803.9 | J2: Кубань УОХ | K2: Преладо | L2: 2/4 | M2: Сайко Василий Викторович | N2: 10:51:42 | O2: 11:42:14 | Q2: 402,002,202,502,001,201 | R2: А816ЕВ | S2: ЕС2898 | T2: 2/4 | U2: =Таблица310[[#This Row],[Регистратор.Номенклатура]] -> Преладо | V2: =18*Таблица310[[#This Row],[Регистратор.Вес нетто]]/69300 -> 3.4883117 | W2: Учхоз Кубань (богара) | X2: богара | Y2: 1 | Z2: 45804 | AC2: 40-52 | AD2: высший | AE2: 44 | AF2: 45804 | AG2: 65889 | AH2: =VLOOKUP(Таблица310[[#This Row],[№ акта]],'Степень зрелости 2025'!$H$13:$I$583,2,FALSE()) -> 40 | AI2: =VLOOKUP(Таблица310[[#This Row],[№ акта]],$AQ$1:$AT$594,2,FALSE()) -> 2/4 | AJ2: =Таблица310[[#This Row],[Регистратор.Номенклатура]] -> Преладо | AK2: =VLOOKUP(Таблица310[[#This Row],[№ акта]],$AQ$1:$AT$594,4,FALSE()) -> Учхоз Кубань (богара) | AL2: =VLOOKUP(Таблица310[[#This Row],[№ акта]],$AQ$1:$AT$594,3,FALSE()) -> 3.4883117 | AM2: =IF(Таблица310[[#This Row],[Площадь уборки, га]]=Таблица310[[#This Row],[Площадь уборки до корр]],"нет","да") -> нет | AN2: =Таблица310[[#This Row],[Площадь уборки до корр]]-Таблица310[[#This Row],[Площадь уборки, га]] -> 0 | AQ2: 44 | AR2: 2/4 | AS2: 3.4883117 | AT2: Учхоз Кубань (богара)
A3: Степень зрелости | B3: 10337.8 | C3: 42 | D3: 45 | E3: 45804 | F3: 28260 | G3: 13970 | H3: 14290 | I3: 10337.8 | J3: Кубань УОХ | K3: Преладо | L3: 2/4 | M3: Чигрин Н.А. | N3: 17:13:45 | O3: 18:08:52 | Q3: 101,301,403,102,302,404 | R3: А819ЕВ | S3: ЕС2899 | T3: 2/4 | U3: =Таблица310[[#This Row],[Регистратор.Номенклатура]] -> Преладо | V3: =18*Таблица310[[#This Row],[Регистратор.Вес нетто]]/69300 -> 3.6285714 | W3: Учхоз Кубань (богара) | X3: богара | Y3: 1 | Z3: 45804 | AC3: 40-52 | AD3: высший | AE3: 45 | AF3: 45804 | AG3: 65901 | AH3: =VLOOKUP(Таблица310[[#This Row],[№ акта]],'Степень зрелости 2025'!$H$13:$I$583,2,FALSE()) -> 42 | AI3: =VLOOKUP(Таблица310[[#This Row],[№ акта]],$AQ$1:$AT$594,2,FALSE()) -> 2/4 | AJ3: =Таблица310[[#This Row],[Регистратор.Номенклатура]] -> Преладо | AK3: =VLOOKUP(Таблица310[[#This Row],[№ акта]],$AQ$1:$AT$594,4,FALSE()) -> Учхоз Кубань (богара) | AL3: =VLOOKUP(Таблица310[[#This Row],[№ акта]],$AQ$1:$AT$594,3,FALSE()) -> 3.6285714 | AM3: =IF(Таблица310[[#This Row],[Площадь уборки, га]]=Таблица310[[#This Row],[Площадь уборки до корр]],"нет","да") -> нет | AN3: =Таблица310[[#This Row],[Площадь уборки до корр]]-Таблица310[[#This Row],[Площадь уборки, га]] -> 0 | AQ3: 45 | AR3: 2/4 | AS3: 3.6285714 | AT3: Учхоз Кубань (богара)
